Workbook

Sheet Listado Hermanos Grupos
A1: Comunidad #4
A2: Fecha de nacimiento comunidad más vieja: | D2: 38326 | F2: =YEAR(TODAY())-(YEAR(D2)) -> 20
A3: Fecha de nacimiento comunidad más joven: | D3: 39516 | F3: =YEAR(TODAY())-(YEAR(D3)) -> 16
A4: Fusión de ambas comunidades: | D4: 44976 | F4: =YEAR(TODAY())-(YEAR(D4)) -> 1
A5: Responsables | D5: Catequistas
A6: 1. Miguel Rodriguez & Rosa Morillo | Mery | D6: José Ramirez | E6: 8299128566 | F6: 8099373926
A7: 2. Edwin García & Sugey Padilla | D7: Chea | E7: 8092385491
A8: 3. Carlos Guevara & Arelis Lazala | D8: Francisco Carmona | E8: 8099638717
A9: 4. Criseida Sánchez | D9: Julia Susana Báez | E9: 8499152003
D10: Carlos M. Vizcaíno | E10: 8098806390
D11: Yacaira De Vizcaíno | E11: 8492437801
A13: Orden Alfabetico | B13: NOMBRE Y APELLIDO | C13: Column1 | D13: TELÉFONO | E13: TELÉFONO2 | F13: Cumpleaños dd/mm | G13: Realidad | H13: Parejas | I13: Sorteo | J13: Hermanos | K13: Matrimonio | L13: Santerio | M13: ws | N13: 39 Hermanos
A14: 1 | B14: Alejandro Nuñez Flaz | C14: ws | D14: 8094262874 | F14: 22293 | G14: Matrimonio | H14: 1 | I14: =RANDBETWEEN(1,4) -> 1 | K14: 1 | L14: N/A | M14: NO WS | N14: 6 Hermanos
A15: 2 | B15: Altagracia Vitello Guzman | C15: ws | D15: 8093306934 | G15: Adultos | I15: =RANDBETWEEN(1,4) -> 4 | J15: 1 | L15: N/A | M15: Angela George
A16: 3 | B16: Ana María Yulis Perreño | C16: ws | D16: 8094421724 | E16: 8096075147 | F16: 28962 | G16: Matrimonio | H16: 2 | K16: 2 | M16: Euridisis Encarnación Reyes
A17: 4 | B17: Angel Gabriel Comas | C17: ws | D17: 8098640272 | E17: 8093337116 | F17: 27103 | G17: Matrimonio | H17: 3 | I17: =RANDBETWEEN(1,4) -> 2 | K17: 3 | M17: Maria Dolores de la Cruz Solano
A18: 5 | B18: Angel Jeremias Florentino de Paula | C18: ws | D18: 8295283435 | E18: 8492063435 | F18: 34757 | G18: Adultos | H18: 2 | I18: =RANDBETWEEN(1,4) -> 4 | J18: 2 | M18: Isabel Concepción
A19: 6 | B19: Angela George | C19: NO ws | D19: 8090000000 | G19: Adultos | I19: =RANDBETWEEN(1,4) -> 2 | J19: 3
A20: 7 | B20: Antonia Polanco P. | C20: ws | D20: 8295264187 | G20: Adultos | I20: =RANDBETWEEN(1,4) -> 2 | J20: 4
A21: 8 | B21: Arelis Lazala de Guevara | C21: ws | D21: 8299032926 | G21: Matrimonio | I21: =RANDBETWEEN(1,4) -> 2 | K21: 4
A22: 9 | B22: Carlos David Baez H. | C22: ws | D22: 8098051308 | E22: 8093639666 | F22: 28670 | G22: Matrimonio | H22: 4 | I22: =RANDBETWEEN(1,4) -> 2 | K22: 5
A23: 10 | B23: Carlos Francisco Guevara | C23: ws | D23: 8092930851 | G23: Matrimonio | I23: =RANDBETWEEN(1,4) -> 3 | K23: 4
A24: 11 | B24: Carmen Herminia Hernandez | C24: ws | D24: 8297635259 | G24: Adultos | I24: =RANDBETWEEN(1,4) -> 1 | J24: 5
A25: 12 | B25: Celeste Regina Núñez Pujols | C25: ws | D25: 8094423992 | E25: 8099058307 | F25: 28292 | G25: Adultos | H25: 2 | I25: =RANDBETWEEN(1,4) -> 4 | J25: 6
A26: 13 | B26: Corina Altagracia Sosa | C26: ws | D26: 8299044766 | G26: Adultos | I26: =RANDBETWEEN(1,4) -> 4 | J26: 7
A27: 14 | B27: Criseida Sánchez | C27: ws | D27: 8097525163 | E27: 8096877177 | F27: 18686 | G27: Adultos | H27: 2 | I27: =RANDBETWEEN(1,4) -> 4 | J27: 8
A28: 15 | B28: Daniel Alexander Gonzalez | C28: ws | D28: 8297932417 | E28: 8096214944 | G28: Matrimonio | I28: =RANDBETWEEN(1,4) -> 1 | K28: 6
A29: 16 | B29: Daysi Francisca Garcia Vasquez | C29: ws | D29: 8292856688 | E29: 8095613159 | F29: 16 Febrero | G29: Adultos | H29: 3 | I29: =RANDBETWEEN(1,4) -> 4 | J29: 9
A30: 17 | B30: Dionis Esteban Alcantara Arias | C30: ws | D30: 8299641681 | F30: 29753 | G30: Matrimonio | H30: 2 | I30: =RANDBETWEEN(1,4) -> 4 | K30: 2
A31: 18 | B31: Edwin García | C31: ws | D31: 8298789120 | F31: 30046 | G31: Matrimonio | H31: 5 | I31: =RANDBETWEEN(1,4) -> 2 | K31: 7
A32: 19 | B32: Eliezer Paniagua | C32: ws | D32: 8298620330 | G32: Adultos | I32: =RANDBETWEEN(1,4) -> 3 | J32: 10
A33: 20 | B33: Elimar Alvarez | C33: ws | D33: 8096191080 | G33: Adultos | I33: =RANDBETWEEN(1,4) -> 1 | J33: 11
A34: 21 | B34: Enmanuel Gonzalez María | C34: ws | D34: 8093380659 | F34: 35559 | G34: Adultos | H34: 4 | I34: =RANDBETWEEN(1,4) -> 4 | J34: 12
A35: 22 | B35: Euridisis Encarnación Reyes | C35: NO ws | D35: 8496348044 | G35: Adultos | I35: =RANDBETWEEN(1,4) -> 1 | J35: 13
A36: 23 | B36: Gisela Antonia Gil | C36: ws | D36: 8095385668 | G36: Adultos | I36: =RANDBETWEEN(1,4) -> 4 | J36: 14
A37: 24 | B37: Hermes Moises Aibar Pontier | C37: ws | D37: 8092450787 | F37: 36376 | G37: Adultos | H37: 5 | I37: =RANDBETWEEN(1,4) -> 1 | J37: 15
A38: 25 | B38: Isabel Concepción | D38: 8295840562 | G38: Adultos | I38: =RANDBETWEEN(1,4) -> 3 | J38: 16
A39: 26 | B39: José Miraye | C39: ws | D39: 8097727170 | G39: Adultos | I39: =RANDBETWEEN(1,4) -> 2 | J39: 17
A40: 27 | B40: Juan Isidro Suliz | C40: ws | D40: 8093779854 | G40: Matrimonio | I40: =RANDBETWEEN(1,4) -> 3 | K40: 8
A41: 28 | B41: Kensy Esperanza Cabrera | C41: ws | D41: 8096533463 | G41: Adultos | I41: =RANDBETWEEN(1,4) -> 3 | J41: 18
...

Sheet sReponsables
C1: Responsables | D1: Aleatorio | E1: # | F1: Sorteo
A2: 1,2 | B2: 1 | C2: Miguel Rodriguez & Rosa Morillo | Mery | D2: =RAND() -> 0.3374293 | E2: =RANK(D2,$D$2:$D$5)+COUNTIF($D$2:D2,D2)-1 -> 3 | F2: =IF(E2=1,C2,IF(E2=2,C3,IF(E2=3,C4,IF(E2=4,C5,)))) -> Carlos Guevara & Arelis Lazala
A3: 3,4 | B3: 2 | C3: Edwin Garcia & Sujey Padilla | D3: =RAND() -> 0.021791727 | E3: =RANK(D3,$D$2:$D$5)+COUNTIF($D$2:D3,D3)-1 -> 4 | F3: =IF(E3=1,C2,IF(E3=2,C3,IF(E3=3,C4,IF(E3=4,C5,IF(E3=5,#REF!,IF(E3=6,#REF!,IF(E3=7,C6,IF(E3=8,C8,IF(E3=9,C9,IF(E3=10,#REF!,IF(E3=11,C10,IF(E3=12,#REF!,IF(E3=13,#REF!,IF(E3=14,C11,IF(E3=15,C17,IF(E3=16,C18,IF(E3=17,C19,IF(E3=18,C20,IF(E3=19,C21,))))))))))))))))))) -> Criseida Sánchez
A4: 5,6 | B4: 3 | C4: Carlos Guevara & Arelis Lazala | D4: =RAND() -> 0.48233376 | E4: =RANK(D4,$D$2:$D$5)+COUNTIF($D$2:D4,D4)-1 -> 2 | F4: =IF(E4=1,C2,IF(E4=2,C3,IF(E4=3,C4,IF(E4=4,C5,IF(E4=5,#REF!,IF(E4=6,#REF!,IF(E4=7,C6,IF(E4=8,C8,IF(E4=9,C9,IF(E4=10,#REF!,IF(E4=11,C10,IF(E4=12,#REF!,IF(E4=13,#REF!,IF(E4=14,C11,IF(E4=15,C17,IF(E4=16,C18,IF(E4=17,C19,IF(E4=18,C20,IF(E4=19,C21,))))))))))))))))))) -> Edwin Garcia & Sujey Padilla
A5: 7 | B5: 4 | C5: Criseida Sánchez | D5: =RAND() -> 0.9474689 | E5: =RANK(D5,$D$2:$D$5)+COUNTIF($D$2:D5,D5)-1 -> 1 | F5: =IF(E5=1,C2,IF(E5=2,C3,IF(E5=3,C4,IF(E5=4,C5,IF(E5=5,#REF!,IF(E5=6,#REF!,IF(E5=7,C6,IF(E5=8,C8,IF(E5=9,C9,IF(E5=10,#REF!,IF(E5=11,C10,IF(E5=12,#REF!,IF(E5=13,#REF!,IF(E5=14,C11,IF(E5=15,C17,IF(E5=16,C18,IF(E5=17,C19,IF(E5=18,C20,IF(E5=19,C21,))))))))))))))))))) -> Miguel Rodriguez & Rosa Morillo | Mery
B7: # | C7: Matrimonios | D7: Aleatorio | E7: # | F7: Sorteo
A8: 8,9 | B8: 1 | C8: Alejandro Flaz & Natalia García | D8: =RAND() -> 0.85414034 | E8: =RANK(D8,$D$8:$D$15)+COUNTIF($D$8:D8,D8)-1 -> 2 | F8: =IF(E8=1,C8,IF(E8=2,C9,IF(E8=3,C10,IF(E8=4,C11,IF(E8=5,C12,IF(E8=6,C13,IF(E8=7,C14,IF(E8=8,C15)))))))) -> Angel Gabriel & Yulissa Peña
A9: 10,11 | B9: 2 | C9: Angel Gabriel & Yulissa Peña | D9: =RAND() -> 0.36308838 | E9: =RANK(D9,$D$8:$D$15)+COUNTIF($D$8:D9,D9)-1 -> 5 | F9: =IF(E9=1,C8,IF(E9=2,C9,IF(E9=3,C10,IF(E9=4,C11,IF(E9=5,C12,IF(E9=6,C13,IF(E9=7,C14,IF(E9=8,C15)))))))) -> Dionis Alcantara & Ana Yulis
A10: 12,13 | B10: 3 | C10: Carlos David & Rosa Dominguez | D10: =RAND() -> 0.7906147 | E10: =RANK(D10,$D$8:$D$15)+COUNTIF($D$8:D10,D10)-1 -> 3 | F10: =IF(E10=1,C8,IF(E10=2,C9,IF(E10=3,C10,IF(E10=4,C11,IF(E10=5,C12,IF(E10=6,C13,IF(E10=7,C14,IF(E10=8,C15)))))))) -> Carlos David & Rosa Dominguez
A11: 14,15 | B11: 4 | C11: Daniel Gonzalez & Winny Lora | D11: =RAND() -> 0.082504049 | E11: =RANK(D11,$D$8:$D$15)+COUNTIF($D$8:D11,D11)-1 -> 8 | F11: =IF(E11=1,C8,IF(E11=2,C9,IF(E11=3,C10,IF(E11=4,C11,IF(E11=5,C12,IF(E11=6,C13,IF(E11=7,C14,IF(E11=8,C15)))))))) -> Mario de la Cruz & Victoria Vasquez
B12: 5 | C12: Dionis Alcantara & Ana Yulis | D12: =RAND() -> 0.94171703 | E12: =RANK(D12,$D$8:$D$15)+COUNTIF($D$8:D12,D12)-1 -> 1 | F12: =IF(E12=1,C8,IF(E12=2,C9,IF(E12=3,C10,IF(E12=4,C11,IF(E12=5,C12,IF(E12=6,C13,IF(E12=7,C14,IF(E12=8,C15)))))))) -> Alejandro Flaz & Natalia García
B13: 6 | C13: Juan Isidro & Sindy Núñez | D13: =RAND() -> 0.31951118 | E13: =RANK(D13,$D$8:$D$15)+COUNTIF($D$8:D13,D13)-1 -> 6 | F13: =IF(E13=1,C8,IF(E13=2,C9,IF(E13=3,C10,IF(E13=4,C11,IF(E13=5,C12,IF(E13=6,C13,IF(E13=7,C14,IF(E13=8,C15)))))))) -> Juan Isidro & Sindy Núñez
B14: 7 | C14: Marcos Ventura & Pilar Calcaño | D14: =RAND() -> 0.23801912 | E14: =RANK(D14,$D$8:$D$15)+COUNTIF($D$8:D14,D14)-1 -> 7 | F14: =IF(E14=1,C8,IF(E14=2,C9,IF(E14=3,C10,IF(E14=4,C11,IF(E14=5,C12,IF(E14=6,C13,IF(E14=7,C14,IF(E14=8,C15)))))))) -> Marcos Ventura & Pilar Calcaño
A15: 16,17 | B15: 8 | C15: Mario de la Cruz & Victoria Vasquez | D15: =RAND() -> 0.7490262 | E15: =RANK(D15,$D$8:$D$15)+COUNTIF($D$8:D15,D15)-1 -> 4 | F15: =IF(E15=1,C8,IF(E15=2,C9,IF(E15=3,C10,IF(E15=4,C11,IF(E15=5,C12,IF(E15=6,C13,IF(E15=7,C14,IF(E15=8,C15)))))))) -> Daniel Gonzalez & Winny Lora
B17: # | C17: Hermanos | D17: Aleatorio | E17: # | F17: Sorteo
A18: 18 | B18: 1 | C18: Altagracia Vitello Guzman | D18: =RAND() -> 0.071221019 | E18: =RANK(D18,$D$18:$D$40)+COUNTIF($D$18:D18,D18)-1 -> 21 | F18: =IF(E18=1,C18,IF(E18=2,C19,IF(E18=3,C20,IF(E18=4,C21,IF(E18=5,C22,IF(E18=6,C23,IF(E18=7,C24,IF(E18=8,C25,IF(E18=9,C26,IF(E18=10,C27,IF(E18=11,C28,IF(E18=12,C29,IF(E18=13,C30,IF(E18=14,C31,IF(E18=15,C32,IF(E18=16,C33,IF(E18=17,C34,IF(E18=18,C35,IF(E18=19,C36,IF(E18=20,C37,IF(E18=21,C38,IF(E18=22,C39,IF(E18=23,C40))))))))))))))))))))))) -> Ruth Divina Alcantara Arias
A19: 19 | B19: 2 | C19: Angel Jeremias Florentino de Paula | D19: =RAND() -> 0.071610919 | E19: =RANK(D19,$D$18:$D$40)+COUNTIF($D$18:D19,D19)-1 -> 20 | F19: =IF(E19=1,C18,IF(E19=2,C19,IF(E19=3,C20,IF(E19=4,C21,IF(E19=5,C22,IF(E19=6,C23,IF(E19=7,C24,IF(E19=8,C25,IF(E19=9,C26,IF(E19=10,C27,IF(E19=11,C28,IF(E19=12,C29,IF(E19=13,C30,IF(E19=14,C31,IF(E19=15,C32,IF(E19=16,C33,IF(E19=17,C34,IF(E19=18,C35,IF(E19=19,C36,IF(E19=20,C37,IF(E19=21,C38,IF(E19=22,C39,IF(E19=23,C40))))))))))))))))))))))) -> Rosa Oliva Sánchez Arias
A20: 20 | B20: 3 | C20: Angela George | D20: =RAND() -> 0.14464275 | E20: =RANK(D20,$D$18:$D$40)+COUNTIF($D$18:D20,D20)-1 -> 18 | F20: =IF(E20=1,C18,IF(E20=2,C19,IF(E20=3,C20,IF(E20=4,C21,IF(E20=5,C22,IF(E20=6,C23,IF(E20=7,C24,IF(E20=8,C25,IF(E20=9,C26,IF(E20=10,C27,IF(E20=11,C28,IF(E20=12,C29,IF(E20=13,C30,IF(E20=14,C31,IF(E20=15,C32,IF(E20=16,C33,IF(E20=17,C34,IF(E20=18,C35,IF(E20=19,C36,IF(E20=20,C37,IF(E20=21,C38,IF(E20=22,C39,IF(E20=23,C40))))))))))))))))))))))) -> Luz Alexa Maria Sanchez
A21: 21 | B21: 4 | C21: Antonia Polanco P. | D21: =RAND() -> 0.53944606 | E21: =RANK(D21,$D$18:$D$40)+COUNTIF($D$18:D21,D21)-1 -> 11 | F21: =IF(E21=1,C18,IF(E21=2,C19,IF(E21=3,C20,IF(E21=4,C21,IF(E21=5,C22,IF(E21=6,C23,IF(E21=7,C24,IF(E21=8,C25,IF(E21=9,C26,IF(E21=10,C27,IF(E21=11,C28,IF(E21=12,C29,IF(E21=13,C30,IF(E21=14,C31,IF(E21=15,C32,IF(E21=16,C33,IF(E21=17,C34,IF(E21=18,C35,IF(E21=19,C36,IF(E21=20,C37,IF(E21=21,C38,IF(E21=22,C39,IF(E21=23,C40))))))))))))))))))))))) -> Enmanuel Gonzalez María
A22: 22 | B22: 5 | C22: Carmen Herminia Hernandez | D22: =RAND() -> 0.61475768 | E22: =RANK(D22,$D$18:$D$40)+COUNTIF($D$18:D22,D22)-1 -> 8 | F22: =IF(E22=1,C18,IF(E22=2,C19,IF(E22=3,C20,IF(E22=4,C21,IF(E22=5,C22,IF(E22=6,C23,IF(E22=7,C24,IF(E22=8,C25,IF(E22=9,C26,IF(E22=10,C27,IF(E22=11,C28,IF(E22=12,C29,IF(E22=13,C30,IF(E22=14,C31,IF(E22=15,C32,IF(E22=16,C33,IF(E22=17,C34,IF(E22=18,C35,IF(E22=19,C36,IF(E22=20,C37,IF(E22=21,C38,IF(E22=22,C39,IF(E22=23,C40))))))))))))))))))))))) -> Daysi Francisca Garcia Vasquez
A23: 23 | B23: 6 | C23: Celeste Regina Núñez Pujols | D23: =RAND() -> 0.31016651 | E23: =RANK(D23,$D$18:$D$40)+COUNTIF($D$18:D23,D23)-1 -> 14 | F23: =IF(E23=1,C18,IF(E23=2,C19,IF(E23=3,C20,IF(E23=4,C21,IF(E23=5,C22,IF(E23=6,C23,IF(E23=7,C24,IF(E23=8,C25,IF(E23=9,C26,IF(E23=10,C27,IF(E23=11,C28,IF(E23=12,C29,IF(E23=13,C30,IF(E23=14,C31,IF(E23=15,C32,IF(E23=16,C33,IF(E23=17,C34,IF(E23=18,C35,IF(E23=19,C36,IF(E23=20,C37,IF(E23=21,C38,IF(E23=22,C39,IF(E23=23,C40))))))))))))))))))))))) -> Hermes Moises Aibar Pontier
A24: 24 | B24: 7 | C24: Corina Altagracia Sosa | D24: =RAND() -> 0.095794565 | E24: =RANK(D24,$D$18:$D$40)+COUNTIF($D$18:D24,D24)-1 -> 19 | F24: =IF(E24=1,C18,IF(E24=2,C19,IF(E24=3,C20,IF(E24=4,C21,IF(E24=5,C22,IF(E24=6,C23,IF(E24=7,C24,IF(E24=8,C25,IF(E24=9,C26,IF(E24=10,C27,IF(E24=11,C28,IF(E24=12,C29,IF(E24=13,C30,IF(E24=14,C31,IF(E24=15,C32,IF(E24=16,C33,IF(E24=17,C34,IF(E24=18,C35,IF(E24=19,C36,IF(E24=20,C37,IF(E24=21,C38,IF(E24=22,C39,IF(E24=23,C40))))))))))))))))))))))) -> Maria Dolores de la Cruz Solano
A25: 25 | B25: 8 | C25: Daysi Francisca Garcia Vasquez | D25: =RAND() -> 0.67792735 | E25: =RANK(D25,$D$18:$D$40)+COUNTIF($D$18:D25,D25)-1 -> 4 | F25: =IF(E25=1,C18,IF(E25=2,C19,IF(E25=3,C20,IF(E25=4,C21,IF(E25=5,C22,IF(E25=6,C23,IF(E25=7,C24,IF(E25=8,C25,IF(E25=9,C26,IF(E25=10,C27,IF(E25=11,C28,IF(E25=12,C29,IF(E25=13,C30,IF(E25=14,C31,IF(E25=15,C32,IF(E25=16,C33,IF(E25=17,C34,IF(E25=18,C35,IF(E25=19,C36,IF(E25=20,C37,IF(E25=21,C38,IF(E25=22,C39,IF(E25=23,C40))))))))))))))))))))))) -> Antonia Polanco P.
A26: 26 | B26: 9 | C26: Eliezer Paniagua | D26: =RAND() -> 0.37857455 | E26: =RANK(D26,$D$18:$D$40)+COUNTIF($D$18:D26,D26)-1 -> 13 | F26: =IF(E26=1,C18,IF(E26=2,C19,IF(E26=3,C20,IF(E26=4,C21,IF(E26=5,C22,IF(E26=6,C23,IF(E26=7,C24,IF(E26=8,C25,IF(E26=9,C26,IF(E26=10,C27,IF(E26=11,C28,IF(E26=12,C29,IF(E26=13,C30,IF(E26=14,C31,IF(E26=15,C32,IF(E26=16,C33,IF(E26=17,C34,IF(E26=18,C35,IF(E26=19,C36,IF(E26=20,C37,IF(E26=21,C38,IF(E26=22,C39,IF(E26=23,C40))))))))))))))))))))))) -> Gisela Antonia Gil
A27: 27 | B27: 10 | C27: Elimar Alvarez | D27: =RAND() -> 0.041267777 | E27: =RANK(D27,$D$18:$D$40)+COUNTIF($D$18:D27,D27)-1 -> 23 | F27: =IF(E27=1,C18,IF(E27=2,C19,IF(E27=3,C20,IF(E27=4,C21,IF(E27=5,C22,IF(E27=6,C23,IF(E27=7,C24,IF(E27=8,C25,IF(E27=9,C26,IF(E27=10,C27,IF(E27=11,C28,IF(E27=12,C29,IF(E27=13,C30,IF(E27=14,C31,IF(E27=15,C32,IF(E27=16,C33,IF(E27=17,C34,IF(E27=18,C35,IF(E27=19,C36,IF(E27=20,C37,IF(E27=21,C38,IF(E27=22,C39,IF(E27=23,C40))))))))))))))))))))))) -> Virginia Carolina
B28: 11 | C28: Enmanuel Gonzalez María | D28: =RAND() -> 0.81286374 | E28: =RANK(D28,$D$18:$D$40)+COUNTIF($D$18:D28,D28)-1 -> 2 | F28: =IF(E28=1,C18,IF(E28=2,C19,IF(E28=3,C20,IF(E28=4,C21,IF(E28=5,C22,IF(E28=6,C23,IF(E28=7,C24,IF(E28=8,C25,IF(E28=9,C26,IF(E28=10,C27,IF(E28=11,C28,IF(E28=12,C29,IF(E28=13,C30,IF(E28=14,C31,IF(E28=15,C32,IF(E28=16,C33,IF(E28=17,C34,IF(E28=18,C35,IF(E28=19,C36,IF(E28=20,C37,IF(E28=21,C38,IF(E28=22,C39,IF(E28=23,C40))))))))))))))))))))))) -> Angel Jeremias Florentino de Paula
B29: 12 | C29: Euridisis Encarnación Reyes | D29: =RAND() -> 0.29988945 | E29: =RANK(D29,$D$18:$D$40)+COUNTIF($D$18:D29,D29)-1 -> 15 | F29: =IF(E29=1,C18,IF(E29=2,C19,IF(E29=3,C20,IF(E29=4,C21,IF(E29=5,C22,IF(E29=6,C23,IF(E29=7,C24,IF(E29=8,C25,IF(E29=9,C26,IF(E29=10,C27,IF(E29=11,C28,IF(E29=12,C29,IF(E29=13,C30,IF(E29=14,C31,IF(E29=15,C32,IF(E29=16,C33,IF(E29=17,C34,IF(E29=18,C35,IF(E29=19,C36,IF(E29=20,C37,IF(E29=21,C38,IF(E29=22,C39,IF(E29=23,C40))))))))))))))))))))))) -> Isabel Concepción
B30: 13 | C30: Gisela Antonia Gil | D30: =RAND() -> 0.288848 | E30: =RANK(D30,$D$18:$D$40)+COUNTIF($D$18:D30,D30)-1 -> 16 | F30: =IF(E30=1,C18,IF(E30=2,C19,IF(E30=3,C20,IF(E30=4,C21,IF(E30=5,C22,IF(E30=6,C23,IF(E30=7,C24,IF(E30=8,C25,IF(E30=9,C26,IF(E30=10,C27,IF(E30=11,C28,IF(E30=12,C29,IF(E30=13,C30,IF(E30=14,C31,IF(E30=15,C32,IF(E30=16,C33,IF(E30=17,C34,IF(E30=18,C35,IF(E30=19,C36,IF(E30=20,C37,IF(E30=21,C38,IF(E30=22,C39,IF(E30=23,C40))))))))))))))))))))))) -> José Miraye
B31: 14 | C31: Hermes Moises Aibar Pontier | D31: =RAND() -> 0.87612816 | E31: =RANK(D31,$D$18:$D$40)+COUNTIF($D$18:D31,D31)-1 -> 1 | F31: =IF(E31=1,C18,IF(E31=2,C19,IF(E31=3,C20,IF(E31=4,C21,IF(E31=5,C22,IF(E31=6,C23,IF(E31=7,C24,IF(E31=8,C25,IF(E31=9,C26,IF(E31=10,C27,IF(E31=11,C28,IF(E31=12,C29,IF(E31=13,C30,IF(E31=14,C31,IF(E31=15,C32,IF(E31=16,C33,IF(E31=17,C34,IF(E31=18,C35,IF(E31=19,C36,IF(E31=20,C37,IF(E31=21,C38,IF(E31=22,C39,IF(E31=23,C40))))))))))))))))))))))) -> Altagracia Vitello Guzman
B32: 15 | C32: Isabel Concepción | D32: =RAND() -> 0.70786274 | E32: =RANK(D32,$D$18:$D$40)+COUNTIF($D$18:D32,D32)-1 -> 3 | F32: =IF(E32=1,C18,IF(E32=2,C19,IF(E32=3,C20,IF(E32=4,C21,IF(E32=5,C22,IF(E32=6,C23,IF(E32=7,C24,IF(E32=8,C25,IF(E32=9,C26,IF(E32=10,C27,IF(E32=11,C28,IF(E32=12,C29,IF(E32=13,C30,IF(E32=14,C31,IF(E32=15,C32,IF(E32=16,C33,IF(E32=17,C34,IF(E32=18,C35,IF(E32=19,C36,IF(E32=20,C37,IF(E32=21,C38,IF(E32=22,C39,IF(E32=23,C40))))))))))))))))))))))) -> Angela George
B33: 16 | C33: José Miraye | D33: =RAND() -> 0.58399677 | E33: =RANK(D33,$D$18:$D$40)+COUNTIF($D$18:D33,D33)-1 -> 10 | F33: =IF(E33=1,C18,IF(E33=2,C19,IF(E33=3,C20,IF(E33=4,C21,IF(E33=5,C22,IF(E33=6,C23,IF(E33=7,C24,IF(E33=8,C25,IF(E33=9,C26,IF(E33=10,C27,IF(E33=11,C28,IF(E33=12,C29,IF(E33=13,C30,IF(E33=14,C31,IF(E33=15,C32,IF(E33=16,C33,IF(E33=17,C34,IF(E33=18,C35,IF(E33=19,C36,IF(E33=20,C37,IF(E33=21,C38,IF(E33=22,C39,IF(E33=23,C40))))))))))))))))))))))) -> Elimar Alvarez
B34: 17 | C34: Kensy Esperanza Cabrera | D34: =RAND() -> 0.61906048 | E34: =RANK(D34,$D$18:$D$40)+COUNTIF($D$18:D34,D34)-1 -> 7 | F34: =IF(E34=1,C18,IF(E34=2,C19,IF(E34=3,C20,IF(E34=4,C21,IF(E34=5,C22,IF(E34=6,C23,IF(E34=7,C24,IF(E34=8,C25,IF(E34=9,C26,IF(E34=10,C27,IF(E34=11,C28,IF(E34=12,C29,IF(E34=13,C30,IF(E34=14,C31,IF(E34=15,C32,IF(E34=16,C33,IF(E34=17,C34,IF(E34=18,C35,IF(E34=19,C36,IF(E34=20,C37,IF(E34=21,C38,IF(E34=22,C39,IF(E34=23,C40))))))))))))))))))))))) -> Corina Altagracia Sosa
B35: 18 | C35: Luz Alexa Maria Sanchez | D35: =RAND() -> 0.598151 | E35: =RANK(D35,$D$18:$D$40)+COUNTIF($D$18:D35,D35)-1 -> 9 | F35: =IF(E35=1,C18,IF(E35=2,C19,IF(E35=3,C20,IF(E35=4,C21,IF(E35=5,C22,IF(E35=6,C23,IF(E35=7,C24,IF(E35=8,C25,IF(E35=9,C26,IF(E35=10,C27,IF(E35=11,C28,IF(E35=12,C29,IF(E35=13,C30,IF(E35=14,C31,IF(E35=15,C32,IF(E35=16,C33,IF(E35=17,C34,IF(E35=18,C35,IF(E35=19,C36,IF(E35=20,C37,IF(E35=21,C38,IF(E35=22,C39,IF(E35=23,C40))))))))))))))))))))))) -> Eliezer Paniagua
B36: 19 | C36: Maria Dolores de la Cruz Solano | D36: =RAND() -> 0.45273672 | E36: =RANK(D36,$D$18:$D$40)+COUNTIF($D$18:D36,D36)-1 -> 12 | F36: =IF(E36=1,C18,IF(E36=2,C19,IF(E36=3,C20,IF(E36=4,C21,IF(E36=5,C22,IF(E36=6,C23,IF(E36=7,C24,IF(E36=8,C25,IF(E36=9,C26,IF(E36=10,C27,IF(E36=11,C28,IF(E36=12,C29,IF(E36=13,C30,IF(E36=14,C31,IF(E36=15,C32,IF(E36=16,C33,IF(E36=17,C34,IF(E36=18,C35,IF(E36=19,C36,IF(E36=20,C37,IF(E36=21,C38,IF(E36=22,C39,IF(E36=23,C40))))))))))))))))))))))) -> Euridisis Encarnación Reyes
B37: 20 | C37: Rosa Oliva Sánchez Arias | D37: =RAND() -> 0.069210414 | E37: =RANK(D37,$D$18:$D$40)+COUNTIF($D$18:D37,D37)-1 -> 22 | F37: =IF(E37=1,C18,IF(E37=2,C19,IF(E37=3,C20,IF(E37=4,C21,IF(E37=5,C22,IF(E37=6,C23,IF(E37=7,C24,IF(E37=8,C25,IF(E37=9,C26,IF(E37=10,C27,IF(E37=11,C28,IF(E37=12,C29,IF(E37=13,C30,IF(E37=14,C31,IF(E37=15,C32,IF(E37=16,C33,IF(E37=17,C34,IF(E37=18,C35,IF(E37=19,C36,IF(E37=20,C37,IF(E37=21,C38,IF(E37=22,C39,IF(E37=23,C40))))))))))))))))))))))) -> Ruth Nathalie Veras Acosta
B38: 21 | C38: Ruth Divina Alcantara Arias | D38: =RAND() -> 0.64624011 | E38: =RANK(D38,$D$18:$D$40)+COUNTIF($D$18:D38,D38)-1 -> 5 | F38: =IF(E38=1,C18,IF(E38=2,C19,IF(E38=3,C20,IF(E38=4,C21,IF(E38=5,C22,IF(E38=6,C23,IF(E38=7,C24,IF(E38=8,C25,IF(E38=9,C26,IF(E38=10,C27,IF(E38=11,C28,IF(E38=12,C29,IF(E38=13,C30,IF(E38=14,C31,IF(E38=15,C32,IF(E38=16,C33,IF(E38=17,C34,IF(E38=18,C35,IF(E38=19,C36,IF(E38=20,C37,IF(E38=21,C38,IF(E38=22,C39,IF(E38=23,C40))))))))))))))))))))))) -> Carmen Herminia Hernandez
B39: 22 | C39: Ruth Nathalie Veras Acosta | D39: =RAND() -> 0.63049903 | E39: =RANK(D39,$D$18:$D$40)+COUNTIF($D$18:D39,D39)-1 -> 6 | F39: =IF(E39=1,C18,IF(E39=2,C19,IF(E39=3,C20,IF(E39=4,C21,IF(E39=5,C22,IF(E39=6,C23,IF(E39=7,C24,IF(E39=8,C25,IF(E39=9,C26,IF(E39=10,C27,IF(E39=11,C28,IF(E39=12,C29,IF(E39=13,C30,IF(E39=14,C31,IF(E39=15,C32,IF(E39=16,C33,IF(E39=17,C34,IF(E39=18,C35,IF(E39=19,C36,IF(E39=20,C37,IF(E39=21,C38,IF(E39=22,C39,IF(E39=23,C40))))))))))))))))))))))) -> Celeste Regina Núñez Pujols
B40: 23 | C40: Virginia Carolina | D40: =RAND() -> 0.22177513 | E40: =RANK(D40,$D$18:$D$40)+COUNTIF($D$18:D40,D40)-1 -> 17 | F40: =IF(E40=1,C18,IF(E40=2,C19,IF(E40=3,C20,IF(E40=4,C21,IF(E40=5,C22,IF(E40=6,C23,IF(E40=7,C24,IF(E40=8,C25,IF(E40=9,C26,IF(E40=10,C27,IF(E40=11,C28,IF(E40=12,C29,IF(E40=13,C30,IF(E40=14,C31,IF(E40=15,C32,IF(E40=16,C33,IF(E40=17,C34,IF(E40=18,C35,IF(E40=19,C36,IF(E40=20,C37,IF(E40=21,C38,IF(E40=22,C39,IF(E40=23,C40))))))))))))))))))))))) -> Kensy Esperanza Cabrera

Sheet xResponsables
B1: Comunidad No. 4 | D1: Presentación de los Temas
B2: Orden | C2: =RANK(C3,$C$3:$H$3) -> 2 | D2: =RANK(D3,$C$3:$H$3) -> 4 | E2: =RANK(E3,$C$3:$H$3) -> 5 | F2: =RANK(F3,$C$3:$H$3) -> 6 | G2: =RANK(G3,$C$3:$H$3) -> 1 | H2: =RANK(H3,$C$3:$H$3) -> 3
C3: =RAND() -> 0.77522848 | D3: =RAND() -> 0.59014982 | E3: =RAND() -> 0.38099832 | F3: =RAND() -> 0.20685223 | G3: =RAND() -> 0.98231256 | H3: =RAND() -> 0.66586261
B4: Tema | C4: =IF(C2=1,C15,IF(C2=2,C16,IF(C2=3,C17,IF(C2=4,C18,IF(C2=5,C19,IF(C2=6,C20)))))) -> Jefté | D4: =IF(D2=1,C15,IF(D2=2,C16,IF(D2=3,C17,IF(D2=4,C18,IF(D2=5,C19,IF(D2=6,C20)))))) -> El delito de Guibeá | E4: =IF(E2=1,C15,IF(E2=2,C16,IF(E2=3,C17,IF(E2=4,C18,IF(E2=5,C19,IF(E2=6,C20)))))) -> Samuel I | F4: =IF(F2=1,C15,IF(F2=2,C16,IF(F2=3,C17,IF(F2=4,C18,IF(F2=5,C19,IF(F2=6,C20)))))) -> Saúl | G4: =IF(G2=1,C15,IF(G2=2,C16,IF(G2=3,C17,IF(G2=4,C18,IF(G2=5,C19,IF(G2=6,C20)))))) -> Abimelek | H4: =IF(H2=1,C15,IF(H2=2,C16,IF(H2=3,C17,IF(H2=4,C18,IF(H2=5,C19,IF(H2=6,C20)))))) -> Sansón
B5: Responsable del Tema | C5: Miguel Rodriguez & Rosa Morillo | Mery | D5: Edwin Garcia & Sujey Padilla | E5: Carlos Guevara & Arelis Lazala | F5: Criseida Sánchez | G5: =sReponsables!F18 -> Ruth Divina Alcantara Arias | H5: =sReponsables!F8 -> Angel Gabriel & Yulissa Peña
B6: Hermanos del Grupo | C6: =sReponsables!F9 -> Dionis Alcantara & Ana Yulis | D6: =sReponsables!F19 -> Rosa Oliva Sánchez Arias | E6: =sReponsables!F10 -> Carlos David & Rosa Dominguez | F6: =sReponsables!F20 -> Luz Alexa Maria Sanchez | G6: =sReponsables!F11 -> Mario de la Cruz & Victoria Vasquez | H6: =sReponsables!F21 -> Enmanuel Gonzalez María
C7: =sReponsables!F22 -> Daysi Francisca Garcia Vasquez | D7: =sReponsables!F12 -> Alejandro Flaz & Natalia García | E7: =sReponsables!F23 -> Hermes Moises Aibar Pontier | F7: =sReponsables!F13 -> Juan Isidro & Sindy Núñez | G7: =sReponsables!F24 -> Maria Dolores de la Cruz Solano | H7: =sReponsables!F14 -> Marcos Ventura & Pilar Calcaño
C8: =sReponsables!F15 -> Daniel Gonzalez & Winny Lora | D8: =sReponsables!F25 -> Antonia Polanco P. | E8: =sReponsables!F26 -> Gisela Antonia Gil | F8: =sReponsables!F27 -> Virginia Carolina | G8: =sReponsables!F28 -> Angel Jeremias Florentino de Paula | H8: =sReponsables!F29 -> Isabel Concepción
C9: =sReponsables!F30 -> José Miraye | D9: =sReponsables!F31 -> Altagracia Vitello Guzman | E9: =sReponsables!F32 -> Angela George | F9: =sReponsables!F33 -> Elimar Alvarez | G9: =sReponsables!F34 -> Corina Altagracia Sosa | H9: =sReponsables!F35 -> Eliezer Paniagua
C10: =sReponsables!F36 -> Euridisis Encarnación Reyes | D10: =sReponsables!F37 -> Ruth Nathalie Veras Acosta | E10: =sReponsables!F38 -> Carmen Herminia Hernandez | F10: =sReponsables!F39 -> Celeste Regina Núñez Pujols | G10: =sReponsables!F40 -> Kensy Esperanza Cabrera
C12: Generar Nuevo Grupo | D12: Coloquese en el Campo Azul y Seleccione Generar Nuevo Grupo
D14: TEMAS celebración, el Azul es por el que vamos
B15: 1 | C15: =Temas!A15 -> Abimelek | D15: Adan | E15: Gedeón | F15: Ester | G15: Naúm
B16: 2 | C16: =Temas!A16 -> Jefté | D16: Eva | E16: Abimelek | F16: Job | G16: Habacuc
B17: 3 | C17: =Temas!A17 -> Sansón | D17: Cain | E17: Jefté | F17: Isaías | G17: Sofonias
B18: 4 | C18: =Temas!A18 -> El delito de Guibeá | D18: Abel | E18: Sansón | F18: Jeremias | G18: Ageo
B19: 5 | C19: =Temas!A19 -> Samuel I | D19: Noe | E19: El delito de Gabaá | F19: Ezequiel | G19: Zacarías
B20: 6 | C20: =Temas!A21 -> Saúl | D20: Abraham | E20: Samuel | F20: Daniel | G20: Malaquias
D21: Isaac | E21: Saúl | F21: Baruc | G21: Esdras
D22: Jacob | E22: David | F22: Oseas | G22: Neemías
D23: José | E23: Salomón | F23: Joel
D24: Moises | E24: Elías | F24: Amós
D25: Aarón | E25: Eliseo | F25: Abdías
D26: Josué | E26: Tobias | F26: Jonás
D27: Débora y Barak | E27: Judit | F27: Miqueas

Sheet sMatrimonio
A1: # | B1: Matrimonio | C1: Aleatorio | D1: # | E1: Sorteado
A2: 1 | B2: Alejandro Flaz & Natalia García | C2: =RAND() -> 0.87477694 | D2: =RANK(C2,$C$2:$C$12)+COUNTIF($C$2:C2,C2)-1 -> 1 | E2: =IF(D2=1,B2,IF(D2=2,B3,IF(D2=3,B4,IF(D2=4,B5,IF(D2=5,B6,IF(D2=6,B7,IF(D2=7,B8,IF(D2=8,B9,IF(D2=9,B10,IF(D2=10,B11,IF(D2=11,B12,))))))))))) -> Alejandro Flaz & Natalia García
A3: 2 | B3: Angel Gabriel & Yulissa Peña | C3: =RAND() -> 0.7308354 | D3: =RANK(C3,$C$2:$C$12)+COUNTIF($C$2:C3,C3)-1 -> 2 | E3: =IF(D3=1,B2,IF(D3=2,B3,IF(D3=3,B4,IF(D3=4,B5,IF(D3=5,B6,IF(D3=6,B7,IF(D3=7,B8,IF(D3=8,B9,IF(D3=9,B10,IF(D3=10,B11,IF(D3=11,B12,))))))))))) -> Angel Gabriel & Yulissa Peña
A4: 3 | B4: Carlos David & Rosa Dominguez | C4: =RAND() -> 0.68910743 | D4: =RANK(C4,$C$2:$C$12)+COUNTIF($C$2:C4,C4)-1 -> 3 | E4: =IF(D4=1,B2,IF(D4=2,B3,IF(D4=3,B4,IF(D4=4,B5,IF(D4=5,B6,IF(D4=6,B7,IF(D4=7,B8,IF(D4=8,B9,IF(D4=9,B10,IF(D4=10,B11,IF(D4=11,B12,))))))))))) -> Carlos David & Rosa Dominguez
A5: 4 | B5: Carlos Guevara & Arelis Lazala | C5: =RAND() -> 0.39512169 | D5: =RANK(C5,$C$2:$C$12)+COUNTIF($C$2:C5,C5)-1 -> 7 | E5: =IF(D5=1,B2,IF(D5=2,B3,IF(D5=3,B4,IF(D5=4,B5,IF(D5=5,B6,IF(D5=6,B7,IF(D5=7,B8,IF(D5=8,B9,IF(D5=9,B10,IF(D5=10,B11,IF(D5=11,B12,))))))))))) -> Edwin García & Sugey Padilla
A6: 5 | B6: Daniel Gonzalez & Winny Lora | C6: =RAND() -> 0.069619887 | D6: =RANK(C6,$C$2:$C$12)+COUNTIF($C$2:C6,C6)-1 -> 10 | E6: =IF(D6=1,B2,IF(D6=2,B3,IF(D6=3,B4,IF(D6=4,B5,IF(D6=5,B6,IF(D6=6,B7,IF(D6=7,B8,IF(D6=8,B9,IF(D6=9,B10,IF(D6=10,B11,IF(D6=11,B12,))))))))))) -> Mario de la Cruz & Victoria Vasquez
A7: 6 | B7: Dionis Alcantara & Ana Yulis | C7: =RAND() -> 0.040754213 | D7: =RANK(C7,$C$2:$C$12)+COUNTIF($C$2:C7,C7)-1 -> 11 | E7: =IF(D7=1,B2,IF(D7=2,B3,IF(D7=3,B4,IF(D7=4,B5,IF(D7=5,B6,IF(D7=6,B7,IF(D7=7,B8,IF(D7=8,B9,IF(D7=9,B10,IF(D7=10,B11,IF(D7=11,B12,))))))))))) -> Miguel Rodriguez & Rosa Morillo | Mery
A8: 7 | B8: Edwin García & Sugey Padilla | C8: =RAND() -> 0.084579467 | D8: =RANK(C8,$C$2:$C$12)+COUNTIF($C$2:C8,C8)-1 -> 9 | E8: =IF(D8=1,B2,IF(D8=2,B3,IF(D8=3,B4,IF(D8=4,B5,IF(D8=5,B6,IF(D8=6,B7,IF(D8=7,B8,IF(D8=8,B9,IF(D8=9,B10,IF(D8=10,B11,IF(D8=11,B12,))))))))))) -> Marcos Ventura & Pilar Calcaño
A9: 8 | B9: Juan Isidro & Sindy Núñez | C9: =RAND() -> 0.59546033 | D9: =RANK(C9,$C$2:$C$12)+COUNTIF($C$2:C9,C9)-1 -> 4 | E9: =IF(D9=1,B2,IF(D9=2,B3,IF(D9=3,B4,IF(D9=4,B5,IF(D9=5,B6,IF(D9=6,B7,IF(D9=7,B8,IF(D9=8,B9,IF(D9=9,B10,IF(D9=10,B11,IF(D9=11,B12,))))))))))) -> Carlos Guevara & Arelis Lazala
A10: 9 | B10: Marcos Ventura & Pilar Calcaño | C10: =RAND() -> 0.57566081 | D10: =RANK(C10,$C$2:$C$12)+COUNTIF($C$2:C10,C10)-1 -> 5 | E10: =IF(D10=1,B2,IF(D10=2,B3,IF(D10=3,B4,IF(D10=4,B5,IF(D10=5,B6,IF(D10=6,B7,IF(D10=7,B8,IF(D10=8,B9,IF(D10=9,B10,IF(D10=10,B11,IF(D10=11,B12,))))))))))) -> Daniel Gonzalez & Winny Lora
A11: 10 | B11: Mario de la Cruz & Victoria Vasquez | C11: =RAND() -> 0.52486765 | D11: =RANK(C11,$C$2:$C$12)+COUNTIF($C$2:C11,C11)-1 -> 6 | E11: =IF(D11=1,B2,IF(D11=2,B3,IF(D11=3,B4,IF(D11=4,B5,IF(D11=5,B6,IF(D11=6,B7,IF(D11=7,B8,IF(D11=8,B9,IF(D11=9,B10,IF(D11=10,B11,IF(D11=11,B12,))))))))))) -> Dionis Alcantara & Ana Yulis
A12: 11 | B12: Miguel Rodriguez & Rosa Morillo | Mery | C12: =RAND() -> 0.25261311 | D12: =RANK(C12,$C$2:$C$12)+COUNTIF($C$2:C12,C12)-1 -> 8 | E12: =IF(D12=1,B2,IF(D12=2,B3,IF(D12=3,B4,IF(D12=4,B5,IF(D12=5,B6,IF(D12=6,B7,IF(D12=7,B8,IF(D12=8,B9,IF(D12=9,B10,IF(D12=10,B11,IF(D12=11,B12,))))))))))) -> Juan Isidro & Sindy Núñez
A14: # | B14: No Matrimonio | C14: Aleatorio | D14: # | E14: Sorteado
A15: 1 | B15: Altagracia Vitello Guzman | C15: =RAND() -> 0.51490094 | D15: =RANK(C15,$C$15:$C$38)+COUNTIF($C$15:C15,C15)-1 -> 10 | E15: =IF(D15=1,B15,IF(D15=2,B16,IF(D15=3,B17,IF(D15=4,B18,IF(D15=5,B19,IF(D15=6,B20,IF(D15=7,B21,IF(D15=8,B22,IF(D15=9,B23,IF(D15=10,B24,IF(D15=11,B25,IF(D15=12,B26,IF(D15=13,B27,IF(D15=14,B28,IF(D15=15,B29,IF(D15=16,B30,IF(D15=17,B31,IF(D15=18,B32,IF(D15=19,B33,IF(D15=20,B34,IF(D15=21,B35,IF(D15=22,B36,IF(D15=23,B37,IF(D15=24,B38)))))))))))))))))))))))) -> Eliezer Paniagua
A16: 2 | B16: Angel Jeremias Florentino de Paula | C16: =RAND() -> 0.34604168 | D16: =RANK(C16,$C$15:$C$38)+COUNTIF($C$15:C16,C16)-1 -> 12 | E16: =IF(D16=1,B15,IF(D16=2,B16,IF(D16=3,B17,IF(D16=4,B18,IF(D16=5,B19,IF(D16=6,B20,IF(D16=7,B21,IF(D16=8,B22,IF(D16=9,B23,IF(D16=10,B24,IF(D16=11,B25,IF(D16=12,B26,IF(D16=13,B27,IF(D16=14,B28,IF(D16=15,B29,IF(D16=16,B30,IF(D16=17,B31,IF(D16=18,B32,IF(D16=19,B33,IF(D16=20,B34,IF(D16=21,B35,IF(D16=22,B36,IF(D16=23,B37,IF(D16=24,B38)))))))))))))))))))))))) -> Enmanuel Gonzalez María
A17: 3 | B17: Angela George | C17: =RAND() -> 0.82393343 | D17: =RANK(C17,$C$15:$C$38)+COUNTIF($C$15:C17,C17)-1 -> 5 | E17: =IF(D17=1,B15,IF(D17=2,B16,IF(D17=3,B17,IF(D17=4,B18,IF(D17=5,B19,IF(D17=6,B20,IF(D17=7,B21,IF(D17=8,B22,IF(D17=9,B23,IF(D17=10,B24,IF(D17=11,B25,IF(D17=12,B26,IF(D17=13,B27,IF(D17=14,B28,IF(D17=15,B29,IF(D17=16,B30,IF(D17=17,B31,IF(D17=18,B32,IF(D17=19,B33,IF(D17=20,B34,IF(D17=21,B35,IF(D17=22,B36,IF(D17=23,B37,IF(D17=24,B38)))))))))))))))))))))))) -> Carmen Herminia Hernandez
A18: 4 | B18: Antonia Polanco P. | C18: =RAND() -> 0.69949265 | D18: =RANK(C18,$C$15:$C$38)+COUNTIF($C$15:C18,C18)-1 -> 8 | E18: =IF(D18=1,B15,IF(D18=2,B16,IF(D18=3,B17,IF(D18=4,B18,IF(D18=5,B19,IF(D18=6,B20,IF(D18=7,B21,IF(D18=8,B22,IF(D18=9,B23,IF(D18=10,B24,IF(D18=11,B25,IF(D18=12,B26,IF(D18=13,B27,IF(D18=14,B28,IF(D18=15,B29,IF(D18=16,B30,IF(D18=17,B31,IF(D18=18,B32,IF(D18=19,B33,IF(D18=20,B34,IF(D18=21,B35,IF(D18=22,B36,IF(D18=23,B37,IF(D18=24,B38)))))))))))))))))))))))) -> Criseida Sánchez
A19: 5 | B19: Carmen Herminia Hernandez | C19: =RAND() -> 0.083710854 | D19: =RANK(C19,$C$15:$C$38)+COUNTIF($C$15:C19,C19)-1 -> 21 | E19: =IF(D19=1,B15,IF(D19=2,B16,IF(D19=3,B17,IF(D19=4,B18,IF(D19=5,B19,IF(D19=6,B20,IF(D19=7,B21,IF(D19=8,B22,IF(D19=9,B23,IF(D19=10,B24,IF(D19=11,B25,IF(D19=12,B26,IF(D19=13,B27,IF(D19=14,B28,IF(D19=15,B29,IF(D19=16,B30,IF(D19=17,B31,IF(D19=18,B32,IF(D19=19,B33,IF(D19=20,B34,IF(D19=21,B35,IF(D19=22,B36,IF(D19=23,B37,IF(D19=24,B38)))))))))))))))))))))))) -> Rosa Oliva Sánchez Arias
A20: 6 | B20: Celeste Regina Núñez Pujols | C20: =RAND() -> 0.051570399 | D20: =RANK(C20,$C$15:$C$38)+COUNTIF($C$15:C20,C20)-1 -> 22 | E20: =IF(D20=1,B15,IF(D20=2,B16,IF(D20=3,B17,IF(D20=4,B18,IF(D20=5,B19,IF(D20=6,B20,IF(D20=7,B21,IF(D20=8,B22,IF(D20=9,B23,IF(D20=10,B24,IF(D20=11,B25,IF(D20=12,B26,IF(D20=13,B27,IF(D20=14,B28,IF(D20=15,B29,IF(D20=16,B30,IF(D20=17,B31,IF(D20=18,B32,IF(D20=19,B33,IF(D20=20,B34,IF(D20=21,B35,IF(D20=22,B36,IF(D20=23,B37,IF(D20=24,B38)))))))))))))))))))))))) -> Ruth Divina Alcantara Arias
A21: 7 | B21: Corina Altagracia Sosa | C21: =RAND() -> 0.90501063 | D21: =RANK(C21,$C$15:$C$38)+COUNTIF($C$15:C21,C21)-1 -> 2 | E21: =IF(D21=1,B15,IF(D21=2,B16,IF(D21=3,B17,IF(D21=4,B18,IF(D21=5,B19,IF(D21=6,B20,IF(D21=7,B21,IF(D21=8,B22,IF(D21=9,B23,IF(D21=10,B24,IF(D21=11,B25,IF(D21=12,B26,IF(D21=13,B27,IF(D21=14,B28,IF(D21=15,B29,IF(D21=16,B30,IF(D21=17,B31,IF(D21=18,B32,IF(D21=19,B33,IF(D21=20,B34,IF(D21=21,B35,IF(D21=22,B36,IF(D21=23,B37,IF(D21=24,B38)))))))))))))))))))))))) -> Angel Jeremias Florentino de Paula
A22: 8 | B22: Criseida Sánchez | C22: =RAND() -> 0.30110858 | D22: =RANK(C22,$C$15:$C$38)+COUNTIF($C$15:C22,C22)-1 -> 14 | E22: =IF(D22=1,B15,IF(D22=2,B16,IF(D22=3,B17,IF(D22=4,B18,IF(D22=5,B19,IF(D22=6,B20,IF(D22=7,B21,IF(D22=8,B22,IF(D22=9,B23,IF(D22=10,B24,IF(D22=11,B25,IF(D22=12,B26,IF(D22=13,B27,IF(D22=14,B28,IF(D22=15,B29,IF(D22=16,B30,IF(D22=17,B31,IF(D22=18,B32,IF(D22=19,B33,IF(D22=20,B34,IF(D22=21,B35,IF(D22=22,B36,IF(D22=23,B37,IF(D22=24,B38)))))))))))))))))))))))) -> Gisela Antonia Gil
A23: 9 | B23: Daysi Francisca Garcia Vasquez | C23: =RAND() -> 0.0073985909 | D23: =RANK(C23,$C$15:$C$38)+COUNTIF($C$15:C23,C23)-1 -> 24 | E23: =IF(D23=1,B15,IF(D23=2,B16,IF(D23=3,B17,IF(D23=4,B18,IF(D23=5,B19,IF(D23=6,B20,IF(D23=7,B21,IF(D23=8,B22,IF(D23=9,B23,IF(D23=10,B24,IF(D23=11,B25,IF(D23=12,B26,IF(D23=13,B27,IF(D23=14,B28,IF(D23=15,B29,IF(D23=16,B30,IF(D23=17,B31,IF(D23=18,B32,IF(D23=19,B33,IF(D23=20,B34,IF(D23=21,B35,IF(D23=22,B36,IF(D23=23,B37,IF(D23=24,B38)))))))))))))))))))))))) -> Virginia Carolina
A24: 10 | B24: Eliezer Paniagua | C24: =RAND() -> 0.13720768 | D24: =RANK(C24,$C$15:$C$38)+COUNTIF($C$15:C24,C24)-1 -> 17 | E24: =IF(D24=1,B15,IF(D24=2,B16,IF(D24=3,B17,IF(D24=4,B18,IF(D24=5,B19,IF(D24=6,B20,IF(D24=7,B21,IF(D24=8,B22,IF(D24=9,B23,IF(D24=10,B24,IF(D24=11,B25,IF(D24=12,B26,IF(D24=13,B27,IF(D24=14,B28,IF(D24=15,B29,IF(D24=16,B30,IF(D24=17,B31,IF(D24=18,B32,IF(D24=19,B33,IF(D24=20,B34,IF(D24=21,B35,IF(D24=22,B36,IF(D24=23,B37,IF(D24=24,B38)))))))))))))))))))))))) -> José Miraye
A25: 11 | B25: Elimar Alvarez | C25: =RAND() -> 0.87372815 | D25: =RANK(C25,$C$15:$C$38)+COUNTIF($C$15:C25,C25)-1 -> 3 | E25: =IF(D25=1,B15,IF(D25=2,B16,IF(D25=3,B17,IF(D25=4,B18,IF(D25=5,B19,IF(D25=6,B20,IF(D25=7,B21,IF(D25=8,B22,IF(D25=9,B23,IF(D25=10,B24,IF(D25=11,B25,IF(D25=12,B26,IF(D25=13,B27,IF(D25=14,B28,IF(D25=15,B29,IF(D25=16,B30,IF(D25=17,B31,IF(D25=18,B32,IF(D25=19,B33,IF(D25=20,B34,IF(D25=21,B35,IF(D25=22,B36,IF(D25=23,B37,IF(D25=24,B38)))))))))))))))))))))))) -> Angela George
A26: 12 | B26: Enmanuel Gonzalez María | C26: =RAND() -> 0.11296489 | D26: =RANK(C26,$C$15:$C$38)+COUNTIF($C$15:C26,C26)-1 -> 18 | E26: =IF(D26=1,B15,IF(D26=2,B16,IF(D26=3,B17,IF(D26=4,B18,IF(D26=5,B19,IF(D26=6,B20,IF(D26=7,B21,IF(D26=8,B22,IF(D26=9,B23,IF(D26=10,B24,IF(D26=11,B25,IF(D26=12,B26,IF(D26=13,B27,IF(D26=14,B28,IF(D26=15,B29,IF(D26=16,B30,IF(D26=17,B31,IF(D26=18,B32,IF(D26=19,B33,IF(D26=20,B34,IF(D26=21,B35,IF(D26=22,B36,IF(D26=23,B37,IF(D26=24,B38)))))))))))))))))))))))) -> Kensy Esperanza Cabrera
A27: 13 | B27: Euridisis Encarnación Reyes | C27: =RAND() -> 0.8663178 | D27: =RANK(C27,$C$15:$C$38)+COUNTIF($C$15:C27,C27)-1 -> 4 | E27: =IF(D27=1,B15,IF(D27=2,B16,IF(D27=3,B17,IF(D27=4,B18,IF(D27=5,B19,IF(D27=6,B20,IF(D27=7,B21,IF(D27=8,B22,IF(D27=9,B23,IF(D27=10,B24,IF(D27=11,B25,IF(D27=12,B26,IF(D27=13,B27,IF(D27=14,B28,IF(D27=15,B29,IF(D27=16,B30,IF(D27=17,B31,IF(D27=18,B32,IF(D27=19,B33,IF(D27=20,B34,IF(D27=21,B35,IF(D27=22,B36,IF(D27=23,B37,IF(D27=24,B38)))))))))))))))))))))))) -> Antonia Polanco P.
A28: 14 | B28: Gisela Antonia Gil | C28: =RAND() -> 0.71795642 | D28: =RANK(C28,$C$15:$C$38)+COUNTIF($C$15:C28,C28)-1 -> 7 | E28: =IF(D28=1,B15,IF(D28=2,B16,IF(D28=3,B17,IF(D28=4,B18,IF(D28=5,B19,IF(D28=6,B20,IF(D28=7,B21,IF(D28=8,B22,IF(D28=9,B23,IF(D28=10,B24,IF(D28=11,B25,IF(D28=12,B26,IF(D28=13,B27,IF(D28=14,B28,IF(D28=15,B29,IF(D28=16,B30,IF(D28=17,B31,IF(D28=18,B32,IF(D28=19,B33,IF(D28=20,B34,IF(D28=21,B35,IF(D28=22,B36,IF(D28=23,B37,IF(D28=24,B38)))))))))))))))))))))))) -> Corina Altagracia Sosa
A29: 15 | B29: Hermes Moises Aibar Pontier | C29: =RAND() -> 0.20789398 | D29: =RANK(C29,$C$15:$C$38)+COUNTIF($C$15:C29,C29)-1 -> 15 | E29: =IF(D29=1,B15,IF(D29=2,B16,IF(D29=3,B17,IF(D29=4,B18,IF(D29=5,B19,IF(D29=6,B20,IF(D29=7,B21,IF(D29=8,B22,IF(D29=9,B23,IF(D29=10,B24,IF(D29=11,B25,IF(D29=12,B26,IF(D29=13,B27,IF(D29=14,B28,IF(D29=15,B29,IF(D29=16,B30,IF(D29=17,B31,IF(D29=18,B32,IF(D29=19,B33,IF(D29=20,B34,IF(D29=21,B35,IF(D29=22,B36,IF(D29=23,B37,IF(D29=24,B38)))))))))))))))))))))))) -> Hermes Moises Aibar Pontier
A30: 16 | B30: Isabel Concepción | C30: =RAND() -> 0.016825095 | D30: =RANK(C30,$C$15:$C$38)+COUNTIF($C$15:C30,C30)-1 -> 23 | E30: =IF(D30=1,B15,IF(D30=2,B16,IF(D30=3,B17,IF(D30=4,B18,IF(D30=5,B19,IF(D30=6,B20,IF(D30=7,B21,IF(D30=8,B22,IF(D30=9,B23,IF(D30=10,B24,IF(D30=11,B25,IF(D30=12,B26,IF(D30=13,B27,IF(D30=14,B28,IF(D30=15,B29,IF(D30=16,B30,IF(D30=17,B31,IF(D30=18,B32,IF(D30=19,B33,IF(D30=20,B34,IF(D30=21,B35,IF(D30=22,B36,IF(D30=23,B37,IF(D30=24,B38)))))))))))))))))))))))) -> Ruth Nathalie Veras Acosta
A31: 17 | B31: José Miraye | C31: =RAND() -> 0.8042396 | D31: =RANK(C31,$C$15:$C$38)+COUNTIF($C$15:C31,C31)-1 -> 6 | E31: =IF(D31=1,B15,IF(D31=2,B16,IF(D31=3,B17,IF(D31=4,B18,IF(D31=5,B19,IF(D31=6,B20,IF(D31=7,B21,IF(D31=8,B22,IF(D31=9,B23,IF(D31=10,B24,IF(D31=11,B25,IF(D31=12,B26,IF(D31=13,B27,IF(D31=14,B28,IF(D31=15,B29,IF(D31=16,B30,IF(D31=17,B31,IF(D31=18,B32,IF(D31=19,B33,IF(D31=20,B34,IF(D31=21,B35,IF(D31=22,B36,IF(D31=23,B37,IF(D31=24,B38)))))))))))))))))))))))) -> Celeste Regina Núñez Pujols
A32: 18 | B32: Kensy Esperanza Cabrera | C32: =RAND() -> 0.11238462 | D32: =RANK(C32,$C$15:$C$38)+COUNTIF($C$15:C32,C32)-1 -> 19 | E32: =IF(D32=1,B15,IF(D32=2,B16,IF(D32=3,B17,IF(D32=4,B18,IF(D32=5,B19,IF(D32=6,B20,IF(D32=7,B21,IF(D32=8,B22,IF(D32=9,B23,IF(D32=10,B24,IF(D32=11,B25,IF(D32=12,B26,IF(D32=13,B27,IF(D32=14,B28,IF(D32=15,B29,IF(D32=16,B30,IF(D32=17,B31,IF(D32=18,B32,IF(D32=19,B33,IF(D32=20,B34,IF(D32=21,B35,IF(D32=22,B36,IF(D32=23,B37,IF(D32=24,B38)))))))))))))))))))))))) -> Luz Alexa Maria Sanchez
A33: 19 | B33: Luz Alexa Maria Sanchez | C33: =RAND() -> 0.3271263 | D33: =RANK(C33,$C$15:$C$38)+COUNTIF($C$15:C33,C33)-1 -> 13 | E33: =IF(D33=1,B15,IF(D33=2,B16,IF(D33=3,B17,IF(D33=4,B18,IF(D33=5,B19,IF(D33=6,B20,IF(D33=7,B21,IF(D33=8,B22,IF(D33=9,B23,IF(D33=10,B24,IF(D33=11,B25,IF(D33=12,B26,IF(D33=13,B27,IF(D33=14,B28,IF(D33=15,B29,IF(D33=16,B30,IF(D33=17,B31,IF(D33=18,B32,IF(D33=19,B33,IF(D33=20,B34,IF(D33=21,B35,IF(D33=22,B36,IF(D33=23,B37,IF(D33=24,B38)))))))))))))))))))))))) -> Euridisis Encarnación Reyes
A34: 20 | B34: Maria Dolores de la Cruz Solano | C34: =RAND() -> 0.41810264 | D34: =RANK(C34,$C$15:$C$38)+COUNTIF($C$15:C34,C34)-1 -> 11 | E34: =IF(D34=1,B15,IF(D34=2,B16,IF(D34=3,B17,IF(D34=4,B18,IF(D34=5,B19,IF(D34=6,B20,IF(D34=7,B21,IF(D34=8,B22,IF(D34=9,B23,IF(D34=10,B24,IF(D34=11,B25,IF(D34=12,B26,IF(D34=13,B27,IF(D34=14,B28,IF(D34=15,B29,IF(D34=16,B30,IF(D34=17,B31,IF(D34=18,B32,IF(D34=19,B33,IF(D34=20,B34,IF(D34=21,B35,IF(D34=22,B36,IF(D34=23,B37,IF(D34=24,B38)))))))))))))))))))))))) -> Elimar Alvarez
A35: 21 | B35: Rosa Oliva Sánchez Arias | C35: =RAND() -> 0.20143503 | D35: =RANK(C35,$C$15:$C$38)+COUNTIF($C$15:C35,C35)-1 -> 16 | E35: =IF(D35=1,B15,IF(D35=2,B16,IF(D35=3,B17,IF(D35=4,B18,IF(D35=5,B19,IF(D35=6,B20,IF(D35=7,B21,IF(D35=8,B22,IF(D35=9,B23,IF(D35=10,B24,IF(D35=11,B25,IF(D35=12,B26,IF(D35=13,B27,IF(D35=14,B28,IF(D35=15,B29,IF(D35=16,B30,IF(D35=17,B31,IF(D35=18,B32,IF(D35=19,B33,IF(D35=20,B34,IF(D35=21,B35,IF(D35=22,B36,IF(D35=23,B37,IF(D35=24,B38)))))))))))))))))))))))) -> Isabel Concepción
A36: 22 | B36: Ruth Divina Alcantara Arias | C36: =RAND() -> 0.65484474 | D36: =RANK(C36,$C$15:$C$38)+COUNTIF($C$15:C36,C36)-1 -> 9 | E36: =IF(D36=1,B15,IF(D36=2,B16,IF(D36=3,B17,IF(D36=4,B18,IF(D36=5,B19,IF(D36=6,B20,IF(D36=7,B21,IF(D36=8,B22,IF(D36=9,B23,IF(D36=10,B24,IF(D36=11,B25,IF(D36=12,B26,IF(D36=13,B27,IF(D36=14,B28,IF(D36=15,B29,IF(D36=16,B30,IF(D36=17,B31,IF(D36=18,B32,IF(D36=19,B33,IF(D36=20,B34,IF(D36=21,B35,IF(D36=22,B36,IF(D36=23,B37,IF(D36=24,B38)))))))))))))))))))))))) -> Daysi Francisca Garcia Vasquez
A37: 23 | B37: Ruth Nathalie Veras Acosta | C37: =RAND() -> 0.1057148 | D37: =RANK(C37,$C$15:$C$38)+COUNTIF($C$15:C37,C37)-1 -> 20 | E37: =IF(D37=1,B15,IF(D37=2,B16,IF(D37=3,B17,IF(D37=4,B18,IF(D37=5,B19,IF(D37=6,B20,IF(D37=7,B21,IF(D37=8,B22,IF(D37=9,B23,IF(D37=10,B24,IF(D37=11,B25,IF(D37=12,B26,IF(D37=13,B27,IF(D37=14,B28,IF(D37=15,B29,IF(D37=16,B30,IF(D37=17,B31,IF(D37=18,B32,IF(D37=19,B33,IF(D37=20,B34,IF(D37=21,B35,IF(D37=22,B36,IF(D37=23,B37,IF(D37=24,B38)))))))))))))))))))))))) -> Maria Dolores de la Cruz Solano
A38: 24 | B38: Virginia Carolina | C38: =RAND() -> 0.98149025 | D38: =RANK(C38,$C$15:$C$38)+COUNTIF($C$15:C38,C38)-1 -> 1 | E38: =IF(D38=1,B15,IF(D38=2,B16,IF(D38=3,B17,IF(D38=4,B18,IF(D38=5,B19,IF(D38=6,B20,IF(D38=7,B21,IF(D38=8,B22,IF(D38=9,B23,IF(D38=10,B24,IF(D38=11,B25,IF(D38=12,B26,IF(D38=13,B27,IF(D38=14,B28,IF(D38=15,B29,IF(D38=16,B30,IF(D38=17,B31,IF(D38=18,B32,IF(D38=19,B33,IF(D38=20,B34,IF(D38=21,B35,IF(D38=22,B36,IF(D38=23,B37,IF(D38=24,B38)))))))))))))))))))))))) -> Altagracia Vitello Guzman

Sheet Salmos
B1: Comunidad No. 4 | D1: Celebración por las casas Salmos/Escrutacio
B2: Tema | C2: =CONCATENATE(Salmos!C11) -> Salmo 7 | D2: =CONCATENATE(Salmos!C11) -> Salmo 7 | E2: =CONCATENATE(Salmos!C11) -> Salmo 7 | F2: =CONCATENATE(Salmos!C11) -> Salmo 7 | G2: =CONCATENATE(Salmos!C11) -> Salmo 7 | H2: =CONCATENATE(Salmos!C11) -> Salmo 7
B3: Hermanos del Grupo | C3: =sMatrimonio!E2 -> Alejandro Flaz & Natalia García | D3: =sMatrimonio!E15 -> Eliezer Paniagua | E3: =sMatrimonio!E3 -> Angel Gabriel & Yulissa Peña | F3: =sMatrimonio!E16 -> Enmanuel Gonzalez María | G3: =sMatrimonio!E4 -> Carlos David & Rosa Dominguez | H3: =sMatrimonio!E17 -> Carmen Herminia Hernandez
C4: =sMatrimonio!E18 -> Criseida Sánchez | D4: =sMatrimonio!E5 -> Edwin García & Sugey Padilla | E4: =sMatrimonio!E19 -> Rosa Oliva Sánchez Arias | F4: =sMatrimonio!E6 -> Mario de la Cruz & Victoria Vasquez | G4: =sMatrimonio!E20 -> Ruth Divina Alcantara Arias | H4: =sMatrimonio!E7 -> Miguel Rodriguez & Rosa Morillo | Mery
C5: =sMatrimonio!E8 -> Marcos Ventura & Pilar Calcaño | D5: =sMatrimonio!E21 -> Angel Jeremias Florentino de Paula | E5: =sMatrimonio!E9 -> Carlos Guevara & Arelis Lazala | F5: =sMatrimonio!E22 -> Gisela Antonia Gil | G5: =sMatrimonio!E10 -> Daniel Gonzalez & Winny Lora | H5: =sMatrimonio!E23 -> Virginia Carolina
C6: =sMatrimonio!E24 -> José Miraye | D6: =sMatrimonio!E11 -> Dionis Alcantara & Ana Yulis | E6: =sMatrimonio!E25 -> Angela George | F6: =sMatrimonio!E12 -> Juan Isidro & Sindy Núñez | G6: =sMatrimonio!E26 -> Kensy Esperanza Cabrera | H6: =sMatrimonio!E27 -> Antonia Polanco P.
C7: =sMatrimonio!E28 -> Corina Altagracia Sosa | D7: =sMatrimonio!E29 -> Hermes Moises Aibar Pontier | E7: =sMatrimonio!E30 -> Ruth Nathalie Veras Acosta | F7: =sMatrimonio!E31 -> Celeste Regina Núñez Pujols | G7: =sMatrimonio!E32 -> Luz Alexa Maria Sanchez | H7: =sMatrimonio!E33 -> Euridisis Encarnación Reyes
C8: =sMatrimonio!E34 -> Elimar Alvarez | D8: =sMatrimonio!E35 -> Isabel Concepción | E8: =sMatrimonio!E36 -> Daysi Francisca Garcia Vasquez | F8: =sMatrimonio!E37 -> Maria Dolores de la Cruz Solano | H8: =sMatrimonio!E38 -> Altagracia Vitello Guzman
C10: Coloquese en el Campo Azul y Seleccione un tema.
C11: Salmo 7

Sheet xMatrimonio
B1: Comunidad No. 4 | D1: Celebración por las casas Escrutacio
B2: Tema | C2: =CONCATENATE(xMatrimonio!C11) -> Saúl | D2: =CONCATENATE(xMatrimonio!C11) -> Saúl | E2: =CONCATENATE(xMatrimonio!C11) -> Saúl | F2: =CONCATENATE(xMatrimonio!C11) -> Saúl | G2: =CONCATENATE(xMatrimonio!C11) -> Saúl | H2: =CONCATENATE(xMatrimonio!C11) -> Saúl
B3: Hermanos del Grupo | C3: =sMatrimonio!E2 -> Alejandro Flaz & Natalia García | D3: =sMatrimonio!E15 -> Eliezer Paniagua | E3: =sMatrimonio!E3 -> Angel Gabriel & Yulissa Peña | F3: =sMatrimonio!E16 -> Enmanuel Gonzalez María | G3: =sMatrimonio!E4 -> Carlos David & Rosa Dominguez | H3: =sMatrimonio!E17 -> Carmen Herminia Hernandez
C4: =sMatrimonio!E18 -> Criseida Sánchez | D4: =sMatrimonio!E5 -> Edwin García & Sugey Padilla | E4: =sMatrimonio!E19 -> Rosa Oliva Sánchez Arias | F4: =sMatrimonio!E6 -> Mario de la Cruz & Victoria Vasquez | G4: =sMatrimonio!E20 -> Ruth Divina Alcantara Arias | H4: =sMatrimonio!E7 -> Miguel Rodriguez & Rosa Morillo | Mery
C5: =sMatrimonio!E8 -> Marcos Ventura & Pilar Calcaño | D5: =sMatrimonio!E21 -> Angel Jeremias Florentino de Paula | E5: =sMatrimonio!E9 -> Carlos Guevara & Arelis Lazala | F5: =sMatrimonio!E22 -> Gisela Antonia Gil | G5: =sMatrimonio!E10 -> Daniel Gonzalez & Winny Lora | H5: =sMatrimonio!E23 -> Virginia Carolina
C6: =sMatrimonio!E24 -> José Miraye | D6: =sMatrimonio!E11 -> Dionis Alcantara & Ana Yulis | E6: =sMatrimonio!E25 -> Angela George | F6: =sMatrimonio!E12 -> Juan Isidro & Sindy Núñez | G6: =sMatrimonio!E26 -> Kensy Esperanza Cabrera | H6: =sMatrimonio!E27 -> Antonia Polanco P.
C7: =sMatrimonio!E28 -> Corina Altagracia Sosa | D7: =sMatrimonio!E29 -> Hermes Moises Aibar Pontier | E7: =sMatrimonio!E30 -> Ruth Nathalie Veras Acosta | F7: =sMatrimonio!E31 -> Celeste Regina Núñez Pujols | G7: =sMatrimonio!E32 -> Luz Alexa Maria Sanchez | H7: =sMatrimonio!E33 -> Euridisis Encarnación Reyes
C8: =sMatrimonio!E34 -> Elimar Alvarez | D8: =sMatrimonio!E35 -> Isabel Concepción | E8: =sMatrimonio!E36 -> Daysi Francisca Garcia Vasquez | F8: =sMatrimonio!E37 -> Maria Dolores de la Cruz Solano | G8: =sMatrimonio!E38 -> Altagracia Vitello Guzman
C10: Coloquese en el Campo Azul y Seleccione un tema.
C11: Saúl

Sheet Eucaristia
B1: Comunidad No. 4 | D1: Presentación Eucaristia
C2: =RANK(C3,$C$3:$H$3) -> 6 | D2: =RANK(D3,$C$3:$H$3) -> 5 | E2: =RANK(E3,$C$3:$H$3) -> 3 | F2: =RANK(F3,$C$3:$H$3) -> 4 | G2: =RANK(G3,$C$3:$H$3) -> 1 | H2: =RANK(H3,$C$3:$H$3) -> 2
C3: =RAND() -> 0.080524167 | D3: =RAND() -> 0.37220501 | E3: =RAND() -> 0.74114682 | F3: =RAND() -> 0.61753551 | G3: =RAND() -> 0.96732557 | H3: =RAND() -> 0.87213725
B4: Responsables | C4: Miguel Rodriguez & Rosa Morillo | Mery | D4: Edwin Garcia & Sujey Padilla | E4: Carlos Guevara & Arelis Lazala | F4: Criseida Sánchez | G4: =sReponsables!F8 -> Angel Gabriel & Yulissa Peña | H4: =sReponsables!F9 -> Dionis Alcantara & Ana Yulis
B5: Hermanos del Grupo | C5: =sReponsables!F10 -> Carlos David & Rosa Dominguez | D5: =sReponsables!F11 -> Mario de la Cruz & Victoria Vasquez | E5: =sReponsables!F12 -> Alejandro Flaz & Natalia García | F5: =sReponsables!F13 -> Juan Isidro & Sindy Núñez | G5: =sReponsables!F14 -> Marcos Ventura & Pilar Calcaño | H5: =sReponsables!F15 -> Daniel Gonzalez & Winny Lora
C6: =sReponsables!F18 -> Ruth Divina Alcantara Arias | D6: =sReponsables!F19 -> Rosa Oliva Sánchez Arias | E6: =sReponsables!F20 -> Luz Alexa Maria Sanchez | F6: =sReponsables!F21 -> Enmanuel Gonzalez María | G6: =sReponsables!F22 -> Daysi Francisca Garcia Vasquez | H6: =sReponsables!F23 -> Hermes Moises Aibar Pontier
C7: =sReponsables!F24 -> Maria Dolores de la Cruz Solano | D7: =sReponsables!F25 -> Antonia Polanco P. | E7: =sReponsables!F26 -> Gisela Antonia Gil | F7: =sReponsables!F27 -> Virginia Carolina | G7: =sReponsables!F28 -> Angel Jeremias Florentino de Paula | H7: =sReponsables!F29 -> Isabel Concepción
C8: =sReponsables!F30 -> José Miraye | D8: =sReponsables!F31 -> Altagracia Vitello Guzman | E8: =sReponsables!F32 -> Angela George | F8: =sReponsables!F33 -> Elimar Alvarez | G8: =sReponsables!F34 -> Corina Altagracia Sosa | H8: =sReponsables!F35 -> Eliezer Paniagua
C9: =sReponsables!F36 -> Euridisis Encarnación Reyes | D9: =sReponsables!F37 -> Ruth Nathalie Veras Acosta | F9: =sReponsables!F38 -> Carmen Herminia Hernandez | G9: =sReponsables!F39 -> Celeste Regina Núñez Pujols

Sheet Temas
A1: Adan | B1: Patriarcas
A2: Eva | B2: Patriarcas
A3: Cain | B3: Patriarcas
A4: Abel | B4: Patriarcas
A5: Noe | B5: Patriarcas
A6: Abraham | B6: Patriarcas
A7: Isaac | B7: Patriarcas
A8: Jacob | B8: Patriarcas
A9: José | B9: Patriarcas
A10: Moises | B10: Caudillos
A11: Aarón | B11: Caudillos
A12: Josué | B12: Caudillos
A13: Débora y Barak | B13: Jueces
A14: Gedeón | B14: =B13 -> Jueces
A15: Abimelek | B15: =B14 -> Jueces
A16: Jefté | B16: =B15 -> Jueces
A17: Sansón | B17: =B16 -> Jueces
A18: El delito de Guibeá | B18: =B17 -> Jueces
A19: Samuel I | B19: =B18 -> Jueces
A20: Samuel II | B20: =B19 -> Jueces
A21: Saúl | B21: Reyes
A22: David | B22: =B21 -> Reyes
A23: Salomón | B23: =B22 -> Reyes
A24: Elías | B24: Profetas I
A25: Eliseo | B25: =B24 -> Profetas I
A26: Tobias | B26: Figuras
A27: Judit | B27: Figuras
A28: Ester | B28: Figuras
A29: Job | B29: Figuras
A30: Isaías | B30: Profetas II
A31: Jeremias | B31: =B30 -> Profetas II
A32: Ezequiel | B32: =B31 -> Profetas II
A33: Daniel | B33: =B32 -> Profetas II
A34: Baruc | B34: =B33 -> Profetas II
A35: Oseas | B35: =B34 -> Profetas II
A36: Joel | B36: =B35 -> Profetas II
A37: Amós | B37: =B36 -> Profetas II
A38: Abdías | B38: =B37 -> Profetas II
A39: Jonás | B39: =B38 -> Profetas II
A40: Miqueas | B40: =B39 -> Profetas II
...

Sheet Pago Salterio
A1: Pago de Salterios Comunidad 4ta
A2: =COUNTIF('Pago Salterio'!$C$4:$C$30, "Pagado") -> 11 | B2: =COUNTIF('Pago Salterio'!$C$4:$C$30, "Pendiente") -> 12 | C2: =COUNTIF('Pago Salterio'!$C$4:$C$30, "N/A") -> 1
A3: NOMBRE Y APELLIDO | B3: TELÉFONO | C3: Pgo Salterio | D3: %
A4: Alejandro Flaz | B4: (809) 426-2874 | C4: Saltario
A5: Ana María Yulis | B5: (809) 442-1724 | C5: Pendiente
A6: Angel Florentino | B6: (829) 528-3435 | C6: Pendiente
A7: Angel Gabriel Comas | B7: (809) 864-0272 | C7: Pagado | D7: =135/140 -> 0.96428571 | E7: 135
A8: Carlos David Baez | B8: (809) 805-1308 | C8: Pagado | D8: =140/140 -> 1 | E8: 140
A9: Celeste Núñez | B9: (809) 442-3992 | C9: Pendiente
A10: Criseida Sánchez | B10: (809) 687-7177 | C10: Pagado | D10: =135/140 -> 0.96428571 | E10: 135
A11: Daysi Garcia | B11: (809) 561-3159 | C11: Pagado | D11: =135/140 -> 0.96428571 | E11: 135
A12: Dionis E. Alcantara | B12: (829) 964-1681 | C12: Saltario
A13: Edwin García | B13: (829) 878-9120 | C13: Pagado | D13: =135/140 -> 0.96428571 | E13: 135
A14: Enmanuel Gonzalez | B14: (809) 338-0659 | C14: Pagado | D14: =135/140 -> 0.96428571 | E14: 135
A15: Moises Aibar | B15: (809) 245-0787 | C15: Pendiente
A16: José Miraye | B16: (809) 772-7170 | C16: Saltario
A17: Marcos Ventura | B17: (809) 818-0266 | C17: Pendiente
A18: Maria Dolores de la Cruz | B18: (809) 561-0991 | C18: Pendiente
A19: Mario de la Cruz | B19: (829) 592-6452 | C19: N/A
A20: Natalia García | B20: (809) 426-2874 | C20: Pendiente
A21: Pilar Calcaño | B21: (809) 271-9165 | C21: Pendiente
A22: Rosa E. Dominguez | B22: (829) 792-6529 | C22: Pagado | D22: =140/140 -> 1
A23: Rosa Sánchez | B23: (809) 313-8343 | C23: Pendiente
A24: Ruth Alcantara | B24: (829) 981-8924 | C24: Pagado
A25: Ruth Veras | B25: (809) 507-9500 | C25: Pendiente
A26: Sindy Núñez | B26: (829) 650-7952 | C26: Pendiente
A27: Sugey Padilla | B27: (829) 640-6688 | C27: Pagado | D27: =135/140 -> 0.96428571
A28: Victoria Vasquez | B28: (829) 379-7534 | C28: Pagado | D28: =85/140 -> 0.60714286
A29: Yulissa Peña | B29: (809) 603-9258 | C29: Pagado | D29: =135/140 -> 0.96428571
A30: Juan Isidro | B30: (809) 377-9854 | C30: Pendiente

Sheet Preparación Temas y Escrutacio
